Workbook

Sheet Dashboard
A1: Hisaab 2026 Dashboard
A2: Clean summary created from the pasted Happy, Dad, and Harsh ledger.
A4: Metric | B4: Amount | D4: Person | E4: Collected
A5: Happy Collections | B5: =SUMIF(Transactions!A:A,"Happy",Transactions!D:D) | D5: Happy | E5: =SUMIF(Transactions!A:A,D5,Transactions!D:D)
A6: Dad Collections | B6: =SUMIF(Transactions!A:A,"Dad",Transactions!D:D) | D6: Dad | E6: =SUMIF(Transactions!A:A,D6,Transactions!D:D)
A7: Harsh Collections | B7: =SUMIF(Transactions!A:A,"Harsh",Transactions!D:D) | D7: Harsh | E7: =SUMIF(Transactions!A:A,D7,Transactions!D:D)
A8: Total Collections | B8: =SUM(B5:B7)
A9: Expected Ledger Total | B9: 5995950
A10: Difference vs Expected | B10: =B8-B9
A11: Cash | B11: 4100000

Sheet Transactions
A1: Transactions
A2: Normalized ledger entries with dates, party names, notes, rates, and side amounts.
A4: Person | B4: Date | C4: Month | D4: Amount | E4: Party / Shop | F4: Notes | G4: Rate / Flag | H4: Side Amount / Note
A5: Happy | B5: 46113 | C5: =IF(ISNUMBER(B5),TEXT(B5,"mmm yyyy"),"No date") | D5: 40000 | E5: Kirayana Wali dukaan | F5: Curtains wala (rodde waali) | G5: 5% | H5: 333750
A6: Happy | B6: 46119 | C6: =IF(ISNUMBER(B6),TEXT(B6,"mmm yyyy"),"No date") | D6: 45000 | E6: Sai Boutique | H6: 680000
A7: Happy | B7: 46122 | C7: =IF(ISNUMBER(B7),TEXT(B7,"mmm yyyy"),"No date") | D7: 10000 | E7: Urban Belize | G7: 5%
A8: Happy | B8: 46129 | C8: =IF(ISNUMBER(B8),TEXT(B8,"mmm yyyy"),"No date") | D8: 30000 | E8: Urban Belize
A9: Happy | B9: 46132 | C9: =IF(ISNUMBER(B9),TEXT(B9,"mmm yyyy"),"No date") | D9: 96800 | E9: Redstone wale ne after plus 10%
A10: Happy | B10: 46133 | C10: =IF(ISNUMBER(B10),TEXT(B10,"mmm yyyy"),"No date") | D10: 111000 | E10: Bhola Prachoon | F10: 14000 (dukaan de khrche da kateya)
A11: Happy | B11: 46140 | C11: =IF(ISNUMBER(B11),TEXT(B11,"mmm yyyy"),"No date") | D11: 100000 | E11: Mobile Pawas Kol
A12: Happy | B12: 46140 | C12: =IF(ISNUMBER(B12),TEXT(B12,"mmm yyyy"),"No date") | D12: 164000 | E12: 99 Guru Kirpa
A13: Happy | B13: 46140 | C13: =IF(ISNUMBER(B13),TEXT(B13,"mmm yyyy"),"No date") | D13: 75000 | E13: 99 Guru Kirpa | F13: 1st Floor
A14: Happy | B14: 46140 | C14: =IF(ISNUMBER(B14),TEXT(B14,"mmm yyyy"),"No date") | D14: 164000 | E14: Kaler Garments
A15: Happy | B15: 46140 | C15: =IF(ISNUMBER(B15),TEXT(B15,"mmm yyyy"),"No date") | D15: 61000 | E15: Kaler Garments | F15: 1st Floor (14000 ktte paudi de)
A16: Happy | B16: 46141 | C16: =IF(ISNUMBER(B16),TEXT(B16,"mmm yyyy"),"No date") | D16: 25000 | E16: Mobile Pawas Kol
A17: Happy | B17: 46141 | C17: =IF(ISNUMBER(B17),TEXT(B17,"mmm yyyy"),"No date") | D17: 16400 | E17: 99 Guru Kirpa | F17: 10% Bottom Shop
A18: Happy | B18: 46143 | C18: =IF(ISNUMBER(B18),TEXT(B18,"mmm yyyy"),"No date") | D18: 200000 | E18: 99 Jasveer
A19: Happy | B19: 46146 | C19: =IF(ISNUMBER(B19),TEXT(B19,"mmm yyyy"),"No date") | D19: 90000 | E19: Spare Parts
A20: Happy | B20: 46148 | C20: =IF(ISNUMBER(B20),TEXT(B20,"mmm yyyy"),"No date") | D20: 125000 | E20: Beaty Fashion Cosmetics
A21: Happy | B21: 46150 | C21: =IF(ISNUMBER(B21),TEXT(B21,"mmm yyyy"),"No date") | D21: 131000 | E21: Sanders Island
A22: Happy | B22: 46152 | C22: =IF(ISNUMBER(B22),TEXT(B22,"mmm yyyy"),"No date") | D22: 72000 | E22: Jassi Nai Kol si jehdi
A23: Happy | B23: 46155 | C23: =IF(ISNUMBER(B23),TEXT(B23,"mmm yyyy"),"No date") | D23: 180000 | E23: Preet Beauty
A24: Happy | B24: 46155 | C24: =IF(ISNUMBER(B24),TEXT(B24,"mmm yyyy"),"No date") | D24: 90000 | E24: Preet Lehnga | F24: 1st Floor
A25: Happy | B25: 46155 | C25: =IF(ISNUMBER(B25),TEXT(B25,"mmm yyyy"),"No date") | D25: 165000 | E25: Preet Lehnga
A26: Happy | B26: 46156 | C26: =IF(ISNUMBER(B26),TEXT(B26,"mmm yyyy"),"No date") | D26: 264000 | E26: Mahaveer Bakery
A27: Happy | B27: 46156 | C27: =IF(ISNUMBER(B27),TEXT(B27,"mmm yyyy"),"No date") | D27: 132000 | E27: Heera Shoes (New Royal)
A28: Happy | B28: 46157 | C28: =IF(ISNUMBER(B28),TEXT(B28,"mmm yyyy"),"No date") | D28: 300000 | E28: Rafooji Kadilayia
A29: Happy | B29: 46158 | C29: =IF(ISNUMBER(B29),TEXT(B29,"mmm yyyy"),"No date") | D29: 52000 | E29: Mobile Lab
A30: Happy | B30: 46158 | C30: =IF(ISNUMBER(B30),TEXT(B30,"mmm yyyy"),"No date") | D30: 260000 | E30: Aujla Lehnga
A31: Happy | B31: 46159 | C31: =IF(ISNUMBER(B31),TEXT(B31,"mmm yyyy"),"No date") | D31: 52000 | E31: Mannat Clothing
A32: Happy | B32: 46160 | C32: =IF(ISNUMBER(B32),TEXT(B32,"mmm yyyy"),"No date") | D32: 143000 | E32: Alex Saloon
A33: Happy | B33: 46162 | C33: =IF(ISNUMBER(B33),TEXT(B33,"mmm yyyy"),"No date") | D33: 85000 | E33: Kirayana Wali dukaan | F33: Curtains wala (rodde waali)
A34: Happy | B34: 46163 | C34: =IF(ISNUMBER(B34),TEXT(B34,"mmm yyyy"),"No date") | D34: 50000 | E34: Syama Attar
A35: Happy | B35: 46163 | C35: =IF(ISNUMBER(B35),TEXT(B35,"mmm yyyy"),"No date") | D35: 300000 | E35: Vinod Shoes
A36: Happy | B36: 46164 | C36: =IF(ISNUMBER(B36),TEXT(B36,"mmm yyyy"),"No date") | D36: 80000 | E36: Urban Touch
A37: Happy | B37: 46166 | C37: =IF(ISNUMBER(B37),TEXT(B37,"mmm yyyy"),"No date") | D37: 300000 | E37: Fulka Booth House
A38: Happy | B38: 46166 | C38: =IF(ISNUMBER(B38),TEXT(B38,"mmm yyyy"),"No date") | D38: 300000 | E38: Ajay Garments
A39: Happy | B39: 46171 | C39: =IF(ISNUMBER(B39),TEXT(B39,"mmm yyyy"),"No date") | D39: 140000 | E39: 7 Hut
A40: Happy | B40: 46170 | C40: =IF(ISNUMBER(B40),TEXT(B40,"mmm yyyy"),"No date") | D40: 5000 | E40: Sai (Tattoo Wala)
A41: Happy | B41: 46089 | C41: =IF(ISNUMBER(B41),TEXT(B41,"mmm yyyy"),"No date") | D41: 8000 | E41: Sai (Daske Wali Zameen 75000 Theke te)
...

Sheet Summary
A1: Summary
A2: Formula-driven totals by person and month.
A4: Person | B4: Collections | C4: Share | D4: Balance vs Share
A5: Happy | B5: =SUMIF(Transactions!A:A,A5,Transactions!D:D) | C5: =Dashboard!$B$8/3 | D5: =C5-B5
A6: Dad | B6: =SUMIF(Transactions!A:A,A6,Transactions!D:D) | C6: =Dashboard!$B$8/3 | D6: =C6-B6
A7: Harsh | B7: =SUMIF(Transactions!A:A,A7,Transactions!D:D) | C7: =Dashboard!$B$8/3 | D7: =C7-B7
A8: Total | B8: =SUM(B5:B7) | C8: =SUM(C5:C7) | D8: =SUM(D5:D7)
A11: Month | B11: Collections
A12: Mar 2026 | B12: =SUMIF(Transactions!C:C,A12,Transactions!D:D)
A13: Apr 2026 | B13: =SUMIF(Transactions!C:C,A13,Transactions!D:D)
A14: May 2026 | B14: =SUMIF(Transactions!C:C,A14,Transactions!D:D)
A15: Jun 2026 | B15: =SUMIF(Transactions!C:C,A15,Transactions!D:D)
A16: No date | B16: =SUMIF(Transactions!C:C,A16,Transactions!D:D)

Sheet Settlement
A1: Settlement
A2: Original lower settlement block preserved in a clear table.
A4: Person / Item | B4: Share / Base | C4: Collected / Paid | D4: Balance | E4: Adjustment / Note
A5: Dad | B5: 1981490 | C5: 680000 | D5: 1301490 | E5: 1138500
A6: Harsh | B6: 1981490 | C6: 333750 | D6: 1647740 | E6: 1484000
A7: Happy | B7: 1981490 | D7: 1150770 | E7: 1477500
A8: Cash | B8: 4100000 | D8: 4100000
A10: Grand Total | B10: 5995950 | C10: 5944470 | D10: =B10-C10
