Workbook

Sheet Overview
A1: Hisaab Overview
A2: Organized summary of rent received, expenses, balances, and notes.
A4: Section | B4: Source | C4: Total | D4: Notes
A5: Rent Received 24-25 | B5: 24-25!C:C | C5: =SUM('24-25'!C:C) | D5: Given Rent column
A6: Rent Received 25-26 | B6: 25-26!C:C | C6: =SUM('25-26'!C:C) | D6: Given Rent column
A7: Expense - All 3 | B7: Expenditure!B:B | C7: =SUM(Expenditure!B:B) | D7: Shared expenses
A8: Expense - Happy and Dad | B8: Expenditure!D:D | C8: =SUM(Expenditure!D:D) | D8: Happy and Dad expenses
A9: Next Year Allotted | B9: Next Year Allotted!A:A | C9: =SUM('Next Year Allotted'!A:A) | D9: Future allotted amounts
A10: 2024 Left | B10: 2024 Left!D:D | C10: =SUM('2024 Left'!D:D) | D10: Left column
A11: Outstanding | B11: Outstanding!B:B | C11: =SUM(Outstanding!B:B) | D11: Outstanding list
A12: Theka Duggal Total | B12: theka!B5 | C12: ='theka'!B5 | D12: Duggal sum
A13: Theka Daska Total | B13: theka!C5 | C13: ='theka'!C5 | D13: Daska sum
A16: Workbook Tabs | B16: Purpose
A17: 24-25 | B17: Rent ledger for financial year 2024-25
A18: 25-26 | B18: Rent ledger for financial year 2025-26
A19: Expenditure | B19: Expense records split by category
A20: theka | B20: Theka calculation and settlement notes
A21: Next Year Allotted | B21: Amounts to be given next year
A22: 2024 Left | B22: Remaining balances from 2024
A23: Misc Amount | B23: Single miscellaneous amount
A24: Misc Notes | B24: Short miscellaneous payment notes
A25: Outstanding | B25: Outstanding/remaining items

Sheet 24-25
A1: Date | B1: Alotted Rent | C1: Given Rent | D1: From? | E1: Name
A2: 45494 | C2: 77000 | D2: Harigarh Wale Ne Ditte | E2: Malwa Collection
A3: 12-Sept-2024 | C3: 56500 | D3: Urban touch | E3: Urban Touch
A4: 21-Sept-2024 | C4: 50000 | D4: Mobile Chahard - Jutti Market
A5: 45655 | C5: 85000 | D5: Kadiyal Parlor 99 wali kol
A6: 23-1-2025 | C6: 10000 | D6: Sai - Nikke Kol C Jehdi
A7: 45903 | C7: 5000
A8: 45903 | C8: 45000
A9: 25-03-2025 | C9: 20000
A10: 25-03-2025 | C10: 100000
A11: 26-03-2025 | C11: 250000
A12: 26-03-2025 | C12: 125000
A13: 45755 | C13: 250000
A14: 45777 | C14: 25000
A15: 45778 | C15: 72000
A16: 45779 | C16: 170000
A17: 45780 | C17: 10000
A18: 45785 | C18: 164000
A19: 45786 | C19: 180000
A20: 45786 | C20: 163500
A21: 45787 | C21: 90000
A22: 45788 | C22: 45000
C23: 88000
C24: 120000
C25: 165000
C26: 165000
C27: 275000
C28: 275000
C29: 100000
C30: 275000
C31: 130000
C32: 245000
C33: 100000
C34: 25000
... C44: 42000
C45: 61000 | D45: Daske Wale
C46: 88000 | D46: Dugal Wale
C47: 5000 | D47: Sayi Daske
C48: 68000 | D48: Tehan Wale Kille Da
C49: =SUM(C2:C48) | D49: Total Happy
...

Sheet 25-26
A1: Date | B1: Alotted Rent | C1: Given Rent | D1: From? | E1: Name
A2: 46107 | C2: 45000 | D2: Gyani Gurjant Toorbanjare Wala Kadai Wala | E2: Pawas kol shop

Sheet Expenditure
A1: Date | B1: Expense(All 3) | D1: Expense (Happy and Dad)
B2: 1500 | C2: Dukaan de Rang | D2: 2000
B3: 100000 | C3: Shed aale mistri | D3: 4500
B4: 1000 | C4: Shere | D4: 2000
B5: 100000 | C5: Nakshe | D5: 4500
B6: 4500 | C6: Mitti Pwai Da | D6: 3500
B7: 800 | C7: Paande Mistriyan | D7: 1000
B8: 6200 | C8: Shutter kewal wali da | D8: 11000
B9: 2000 | C9: Dugg Saaf krwayi | D9: 14800 | F9: Happy De ke Aya Rang wale nu
B10: 2000 | C10: Shere Mistri Paleta | D10: =SUM(D2:D9)
B11: 8500 | C11: Tile Wale
B12: 3000 | C12: Kisaan
B13: 12460 | C13: Pawan Baniya
B14: 5200 | C14: Modi Baans
B15: 3500 | C15: Bindr
B16: 93300 | C16: Commety Tax
B17: 1500 | C17: Houdi Saaf
B18: 17500 | C18: Motor Daske New
B19: 2800 | C19: Khanjura
B20: 1800 | C20: JCB
B21: 2400 | C21: Khanjuira Toye pakke
B22: 2600 | C22: Mlwa chakaya
... B29: 23000 | C29: Mobile Shop Kamm Karwaya
B30: =SUM(B2:B29) | C30: Happy
B31: 2100 | C31: Hydra
B32: =SUM(B31) | C32: Dad
B33: 15500 | C33: Khajura Upfront
B34: 30000 | C34: Khajura
B35: 7580 | C35: Motor Bill
B36: 5249 | C36: Motor Bill
B37: =SUM(B33:B36) | C37: Harsh
B39: =B30+B32+B37

Sheet theka
B1: Duggal | C1: Daska
A2: Dad | B2: 157625 | C2: 365000
A3: Harsh | B3: 157625 | C3: 365000
A4: Papa | B4: 135000 | C4: 365000
A5: Sum | B5: =SUM(B2:B4) | C5: =SUM(C2:C4)
A6: Each | B6: =B5/3
B7: =B3-B6
A9: Kille Da Rate | B9: 78000 | C9: 72000
A10: Kille | B10: 13 | C10: 31
A12: Six Month Rate | B12: =(B9*B10)/2 | C12: =(C9*C10)/2
A13: Left | B13: =B12-B5 | C13: =C12-C5

Sheet Next Year Allotted
A1: Alloted | B1: Will be given next year
A3: 165000 | C3: Khadiyal Wali/Wala
A4: 125000 | C4: Phone Wala - Khurana Garment kol
A5: 165000 | C5: Suhag Goldy
A6: 275000 | C6: Kadiyalia Refugee
A7: 44000 | C7: Portronics
A8: 45000 | B8: 33750 | C8: Second Last near gate | D8: 45664

Sheet 2024 Left
D1: Left
A2: 90000 | B2: Satpal Khadiyal | C2: 85000 | D2: =A2-C2
A3: 75000 | B3: TurbanJare | C3: 70000 | D3: =A3-C3

Sheet Misc Amount
A1: 5000

Sheet Misc Notes
A1: 61000 | B1: Daske wale ne kharcha ktt ke
A2: 88000 | B2: Dugal ale ne ditte
A3: 5000 | B3: daske wale di saayi
A4: 68000 | B4: tehan wle de kille de

Sheet Outstanding
A1: Khadar Pandar/Rodda Mistri | B1: 40000
A2: Alex | B2: 13000
A3: Khadiyal Mahi Satpal | B3: 85000
A4: Toorbanjara Parlour | B4: 5000
A5: Chahad Mobile | B5: 10000
